
Running tests...
----------------------------------------------------------------------
......................................E.....................
======================================================================
ERROR [0.020s]: testTc1Valid (test_room_reservation_tests.TestRoomReservation)
Valid case in which all the information is correct and the person
----------------------------------------------------------------------
Traceback (most recent call last):
  File "C:\Users\izans\AppData\Local\Programs\Python\Python310\lib\unittest\case.py", line 59, in testPartExecutor
    yield
  File "C:\Users\izans\AppData\Local\Programs\Python\Python310\lib\unittest\case.py", line 591, in run
    self._callTestMethod(testMethod)
  File "C:\Users\izans\AppData\Local\Programs\Python\Python310\lib\unittest\case.py", line 549, in _callTestMethod
    method()
  File "c:\users\izans\g88.2024.t05.ge2\src\unittest\python\test_room_reservation_tests.py", line 17, in testTc1Valid
    value = myManager.roomReservation(*info)
  File "c:\users\izans\g88.2024.t05.ge2\src\main\python\UC3MTravel\HotelManager.py", line 170, in roomReservation
    raise hotelManagementException(f"{name_surname} already has a "
UC3MTravel.HotelManagementException.hotelManagementException: Santiago P already has a reservation

----------------------------------------------------------------------
Ran 60 tests in 1.125s

FAILED (errors=1)

Generating XML reports...
